(dp1
S'output'
p2
S"<type 'exceptions.SyntaxError'> Adapter not found for google:datastore"
p3
sS'layer'
p4
S'/Users/ecain/Projects/SOTA/web2py/applications/SOTA/models/db.py'
p5
sS'code'
p6
S'<code object <module> at 0x106569230, file "/Users/ecain/Projects/SOTA/web2py/applications/SOTA/models/db.py", line 8>'
p7
sS'snapshot'
p8
(dp9
sS'traceback'
p10
S'Traceback (most recent call last):\n  File "/Users/ecain/Projects/SOTA/web2py/gluon/restricted.py", line 216, in restricted\n    exec(ccode, environment)\n  File "/Users/ecain/Projects/SOTA/web2py/applications/SOTA/models/db.py", line 35, in <module>\n    fake_migrate_all=True)\n  File "/Users/ecain/Projects/SOTA/web2py/gluon/packages/dal/pydal/base.py", line 170, in __call__\n    obj = super(MetaDAL, cls).__call__(*args, **kwargs)\n  File "/Users/ecain/Projects/SOTA/web2py/gluon/packages/dal/pydal/base.py", line 454, in __init__\n    adapter = adapters.get_for(self._dbname)\n  File "/Users/ecain/Projects/SOTA/web2py/gluon/packages/dal/pydal/adapters/__init__.py", line 20, in get_for\n    \'Adapter not found for %s\' % uri\nSyntaxError: Adapter not found for google:datastore\n'
p11
s.