(dp1
S'output'
p2
S"<class 'sqlite3.IntegrityError'> FOREIGN KEY constraint failed"
p3
sS'layer'
p4
S'/Users/ecain/Projects/SOTA/web2py/applications/SOTA/controllers/default.py'
p5
sS'code'
p6
S'<code object <module> at 0x10eaf7ab0, file "/Users/ecain/Projects/SOTA/web2py/applications/SOTA/controllers/default.py:user", line 10>'
p7
sS'snapshot'
p8
(dp9
sS'traceback'
p10
S'Traceback (most recent call last):\n  File "/Users/ecain/Projects/SOTA/web2py/gluon/restricted.py", line 216, in restricted\n    exec(ccode, environment)\n  File "/Users/ecain/Projects/SOTA/web2py/applications/SOTA/controllers/default.py:user", line 174, in <module>\n  File "/Users/ecain/Projects/SOTA/web2py/gluon/globals.py", line 405, in <lambda>\n    self._caller = lambda f: f()\n  File "/Users/ecain/Projects/SOTA/web2py/applications/SOTA/controllers/default.py:user", line 51, in user\n  File "/Users/ecain/Projects/SOTA/web2py/gluon/tools.py", line 1998, in __call__\n    return getattr(self, args[0])()\n  File "/Users/ecain/Projects/SOTA/web2py/gluon/tools.py", line 3308, in logout\n    self.log_event(log, self.user)\n  File "/Users/ecain/Projects/SOTA/web2py/gluon/tools.py", line 2593, in log_event\n    self.table_event().insert(description=str(description % vars), origin=origin, user_id=user_id)\n  File "/usr/local/lib/python2.7/site-packages/pydal/objects.py", line 741, in insert\n    ret = self._db._adapter.insert(self, self._listify(fields))\n  File "/usr/local/lib/python2.7/site-packages/pydal/adapters/base.py", line 492, in insert\n    raise e\nIntegrityError: FOREIGN KEY constraint failed\n'
p11
s.