(dp1
S'output'
p2
S"<type 'exceptions.ValueError'> dictionary update sequence element #0 has length 3; 2 is required"
p3
sS'layer'
p4
S'/Users/ecain/Projects/SOTA/web2py/applications/SOTA/controllers/default.py'
p5
sS'code'
p6
S'<code object <module> at 0x1085b9c30, file "/Users/ecain/Projects/SOTA/web2py/applications/SOTA/controllers/default.py:index", line 10>'
p7
sS'snapshot'
p8
(dp9
sS'traceback'
p10
S'Traceback (most recent call last):\n  File "/Users/ecain/Projects/SOTA/web2py/gluon/restricted.py", line 216, in restricted\n    exec(ccode, environment)\n  File "/Users/ecain/Projects/SOTA/web2py/applications/SOTA/controllers/default.py:index", line 151, in <module>\n  File "/Users/ecain/Projects/SOTA/web2py/gluon/globals.py", line 405, in <lambda>\n    self._caller = lambda f: f()\n  File "/Users/ecain/Projects/SOTA/web2py/gluon/tools.py", line 4321, in f\n    return action(*a, **b)\n  File "/Users/ecain/Projects/SOTA/web2py/applications/SOTA/controllers/default.py:index", line 32, in index\n  File "/Users/ecain/Projects/SOTA/web2py/gluon/tools.py", line 4321, in f\n    return action(*a, **b)\n  File "/Users/ecain/Projects/SOTA/web2py/applications/SOTA/controllers/default.py:index", line 149, in database_contents\nValueError: dictionary update sequence element #0 has length 3; 2 is required\n'
p11
s.